<mujoco>
    <body name="robot0:base_link" pos="0. 0. 0.25">
        <!-- <joint armature="0.0001" axis="1 0 0" damping="1e+11" name="robot0:slide0" pos="0 0 0" type="slide"></joint>
        <joint armature="0.0001" axis="0 1 0" damping="1e+11" name="robot0:slide1" pos="0 0 0" type="slide"></joint>
        <joint armature="0.0001" axis="0 0 1" damping="1e+11" name="robot0:slide2" pos="0 0 0" type="slide"></joint> -->

        <!-- <joint name="wrist_x_slide_joint" damping="100" type="slide" pos="0 0 0" axis="1 0 0" limited="true" range="-1.0 1.0" />
        <joint name="wrist_y_slide_joint" damping="100" type="slide" pos="0 0 0" axis="0 1 0" limited="true" range="-1.0 1.0" />
        <joint name="wrist_z_slide_joint" damping="1000" type="slide" pos="0 0 0" axis="0 0 1" limited="true" range="-1.0 1.0" />
        <joint name="wrist_z_hinge_joint" damping="200" type="hinge" pos="0 0 0" axis="0 0 1" limited="true" range="-1.57 1.57" />
        <joint name="wrist_y_hinge_joint" damping="200" type="hinge" pos="0 0 0" axis="0 1 0" limited="true" range="-1.57 1.57" />
        <joint name="wrist_x_hinge_joint" damping="200" type="hinge" pos="0 0 0" axis="1 0 0" limited="true" range="-1.57 1.57" /> -->

        <geom type="mesh" mesh="H026994 - A35 M-2 PEDESTAL ASSY - SHAREABLE" />
        <geom type="mesh" contype="0" conaffinity="0" group="1" rgba="0.784314 0.784314 0.784314 1" mesh="H026994 - A35 M-2 PEDESTAL ASSY - SHAREABLE" />
        <body name="drive1_link" pos="0 0 0.08335" quat="0.707107 0 0 -0.707107">
            <inertial pos="0 0 0" mass="1" diaginertia="0.005 0.005 0.005" />
            <joint name="hdt_drive1_joint" pos="0 0 0" axis="0 0 1" limited="true" range="-6.28319 6.28319" damping="150" />
            <geom type="mesh" mesh="H024840 - A35 M-2 DRIVE MODULE, SHAREABLE" />
            <geom type="mesh" contype="0" conaffinity="0" group="1" rgba="0.784314 0.784314 0.784314 1" mesh="H024840 - A35 M-2 DRIVE MODULE, SHAREABLE" />
            <body name="drive2_link" pos="0.07155 0 0" quat="0.707107 0 -0.707107 0">
                <inertial pos="0.17855 0 0" quat="0.5 0.5 0.5 0.5" mass="3" diaginertia="0.0787602 0.0787602 0.015" />
                <joint name="hdt_drive2_joint" pos="0 0 0" axis="0 0 1" limited="true" range="-1.5708 1.5708" damping="150" />
                <geom quat="0 1 0 0" type="mesh" mesh="H024840 - A35 M-2 DRIVE MODULE, SHAREABLE" />
                <geom quat="0 1 0 0" type="mesh" contype="0" conaffinity="0" group="1" rgba="0.784314 0.784314 0.784314 1" mesh="H024840 - A35 M-2 DRIVE MODULE, SHAREABLE" />
                <geom pos="0.17855 0 0" type="mesh" mesh="H024847 - A35 M-2 PROXIMAL TUBE ASSY - SHAREABLE" />
                <geom pos="0.17855 0 0" type="mesh" contype="0" conaffinity="0" group="1" rgba="0.784314 0.784314 0.784314 1" mesh="H024847 - A35 M-2 PROXIMAL TUBE ASSY - SHAREABLE" />
                <geom pos="0.3571 0 0" quat="0 0 1 0" type="mesh" mesh="H024840 - A35 M-2 DRIVE MODULE, SHAREABLE" />
                <geom pos="0.3571 0 0" quat="0 0 1 0" type="mesh" contype="0" conaffinity="0" group="1" rgba="0.784314 0.784314 0.784314 1" mesh="H024840 - A35 M-2 DRIVE MODULE, SHAREABLE" />
                <body name="drive3_link" pos="0.3571 0 0.07155">
                    <inertial pos="0 0 0" quat="0.5 0.5 0.5 -0.5" mass="1" diaginertia="0.005 0.005 0.005" />
                    <joint name="hdt_drive3_joint" pos="0 0 0" axis="0 0 1" limited="true" range="-4.49 1.35" damping="150" />
                    <geom quat="0.5 0.5 0.5 -0.5" type="mesh" mesh="H024840 - A35 M-2 DRIVE MODULE, SHAREABLE" />
                    <geom quat="0.5 0.5 0.5 -0.5" type="mesh" contype="0" conaffinity="0" group="1" rgba="0.784314 0.784314 0.784314 1" mesh="H024840 - A35 M-2 DRIVE MODULE, SHAREABLE" />
                    <body name="drive4_link" pos="0 0.142 0" quat="0.707107 -0.707107 0 0">
                        <inertial pos="0 0 0.064775" mass="2" diaginertia="0.0183916 0.0183916 0.01" />
                        <joint name="hdt_drive4_joint" pos="0 0 0" axis="0 0 1" limited="true" range="-6.28319 6.28319" damping="70" />
                        <geom quat="0 1 0 0" type="mesh" mesh="H024848 - A35 M-2 DISTAL TUBE ASSY - SHAREABLE" />
                        <geom quat="0 1 0 0" type="mesh" contype="0" conaffinity="0" group="1" rgba="0.784314 0.784314 0.784314 1" mesh="H024848 - A35 M-2 DISTAL TUBE ASSY - SHAREABLE" />
                        <geom pos="0 0 0.12955" quat="-0.5 0.5 -0.5 -0.5" type="mesh" mesh="H024840 - A35 M-2 DRIVE MODULE, SHAREABLE" />
                        <geom pos="0 0 0.12955" quat="-0.5 0.5 -0.5 -0.5" type="mesh" contype="0" conaffinity="0" group="1" rgba="0.784314 0.784314 0.784314 1" mesh="H024840 - A35 M-2 DRIVE MODULE, SHAREABLE" />
                        <body name="drive5_link" pos="0 -0.07155 0.12955" quat="-0.5 -0.5 0.5 -0.5">
                            <inertial pos="0 0 0" mass="1" diaginertia="0.005 0.005 0.005" />
                            <joint name="hdt_drive5_joint" pos="0 0 0" axis="0 0 1" limited="true" range="-6.28319 6.28319" damping="70" />
                            <geom quat="0 -0.707107 0 0.707107" type="mesh" mesh="H024840 - A35 M-2 DRIVE MODULE, SHAREABLE" />
                            <geom quat="0 -0.707107 0 0.707107" type="mesh" contype="0" conaffinity="0" group="1" rgba="0.784314 0.784314 0.784314 1" mesh="H024840 - A35 M-2 DRIVE MODULE, SHAREABLE" />
                            <body name="ee_link" pos="0.0885 0 0" quat="0.707107 0 0.707107 0">
                                <inertial pos="0 0 0" mass="1" diaginertia="0.005 0.005 0.005" />
                                <joint name="hdt_drive6_joint" pos="0 0 0" axis="0 0 1" limited="true" range="-6.28319 6.28319" damping="70" />
                                <geom quat="0.5 0.5 0.5 -0.5" type="mesh" mesh="H024842 - A35 M-2 PINCER ASSY - SHAREABLE, UNDERWATER" />
                                <geom quat="0.5 0.5 0.5 -0.5" type="mesh" contype="0" conaffinity="0" group="1" rgba="0.784314 0.784314 0.784314 1" mesh="H024842 - A35 M-2 PINCER ASSY - SHAREABLE, UNDERWATER" />

                                <site name="r_grip_site" pos="0.0 0. 0.1" size="0.03" rgba="0 0 1 0.5" type="sphere" group="1"/>

                                <!-- <body name="gripper" pos="-1e-05 -0.07 0.02793">
                                    <geom name="hdt_mk3_m_palm"  type="mesh" mesh="hdt_mk3_m_palm" />
                                    
                                </body> -->

                                <body name="pincer_link1" pos="0.0135 0 0.0375" quat="0.5 -0.5 -0.5 -0.5">
                                    <inertial pos="0.0607647 0.00559547 -3.99908e-06" quat="0.0177323 0.706938 -0.0180733 0.706822" mass="0.0659882" diaginertia="0.00012599 0.000120886 7.08563e-06" />
                                    <joint name="hdt_pincer_joint1" pos="0 0 0" axis="0 0 1" limited="true" range="-0.2 0.9" damping="15" />
                                    <geom quat="0 1 0 0" type="mesh" mesh="H022927 - A35 PINCER FINGER, LONG, OVERMOLD ASSY - SHAREABLE" />
                                    <geom quat="0 1 0 0" type="mesh" contype="0" conaffinity="0" group="1" rgba="0.784314 0.784314 0.784314 1" mesh="H022927 - A35 PINCER FINGER, LONG, OVERMOLD ASSY - SHAREABLE" />
                                </body>
                                <body name="pincer_link2" pos="-0.0135 0 0.0375" quat="0.5 0.5 -0.5 0.5">
                                    <inertial pos="0.0607647 0.00559547 -3.99908e-06" quat="0.0177323 0.706938 -0.0180733 0.706822" mass="0.0659882" diaginertia="0.00012599 0.000120886 7.08563e-06" />
                                    <joint name="hdt_pincer_joint2" pos="0 0 0" axis="0 0 1" limited="true" range="-0.2 1" damping="7" />
                                    <geom quat="0 1 0 0" type="mesh" mesh="H022927 - A35 PINCER FINGER, LONG, OVERMOLD ASSY - SHAREABLE" />
                                    <geom quat="0 1 0 0" type="mesh" contype="0" conaffinity="0" group="1" rgba="0.784314 0.784314 0.784314 1" mesh="H022927 - A35 PINCER FINGER, LONG, OVERMOLD ASSY - SHAREABLE" />
                                </body>
                            </body>
                        </body>
                    </body>
                </body>
            </body>
        </body>
    </body>
</mujoco>
