<?xml version="1.0" ?>
<!-- =================================================================================== -->
<!-- |    This document was autogenerated by xacro from hdt_angler_mujoco.xacro        | -->
<!-- |    EDITING THIS FILE BY HAND IS NOT RECOMMENDED                                 | -->
<!-- =================================================================================== -->
<robot name="hdt_arm" xmlns:xacro="http://www.ros.org/wiki/xacro">
  <mujoco>
    <compiler balanceinertia="true" discardvisual="false" fusestatic="true" meshdir="../meshes/" strippath="true"/>
  </mujoco>
  <!-- materials -->
  <material name="black">
    <color rgba="0.78431372549 0.78431372549 0.78431372549 1.0"/>
  </material>
  <material name="grey">
    <color rgba="0.250980392157 0.250980392157 0.250980392157 1.0"/>
  </material>
  <material name="yellow">
    <color rgba="0.941176470588 0.878431372549 0.250980392157 1.0"/>
  </material>
  <!-- segment 0 -->
  <link name="base_link"/>
  <!-- pedestal -->
  <joint name="pedestal_joint" type="fixed">
    <origin rpy="0 0 0" xyz="0 0 0"/>
    <parent link="base_link"/>
    <child link="pedestal_link"/>
  </joint>
  <link name="pedestal_link">
    <collision>
      <origin rpy="0 0 0" xyz="0 0 0"/>
      <geometry>
        <mesh filename="package://hdt_angler_description/meshes/H026994 - A35 M-2 PEDESTAL ASSY - SHAREABLE.STL"/>
      </geometry>
    </collision>
    <visual>
      <origin rpy="0 0 0" xyz="0 0 0"/>
      <geometry>
        <mesh filename="package://hdt_angler_description/meshes/H026994 - A35 M-2 PEDESTAL ASSY - SHAREABLE.STL"/>
      </geometry>
      <material name="black"/>
    </visual>
    <inertial>
      <origin rpy="0 0 0" xyz="0 0 0"/>
      <mass value="1"/>
      <inertia ixx="0.005" ixy="0.0" ixz="0.0" iyy="0.005" iyz="0.0" izz="0.005"/>
    </inertial>
  </link>
  <!-- drive 1 -->
  <joint name="drive1_joint" type="revolute">
    <axis xyz="0 0 1"/>
    <limit effort="60.0" lower="-6.28318530718" upper="6.28318530718" velocity="0.785398163397"/>
    <origin rpy="0 0 -1.57079632679" xyz="0 0 0.08335"/>
    <parent link="pedestal_link"/>
    <child link="drive1_link"/>
    <dynamics damping="0.7" friction="0.0"/>
  </joint>
  <link name="drive1_link">
    <collision>
      <origin rpy="0 0 0" xyz="0 0 0"/>
      <geometry>
        <mesh filename="package://hdt_angler_description/meshes/H024840 - A35 M-2 DRIVE MODULE, SHAREABLE.STL"/>
      </geometry>
    </collision>
    <visual>
      <origin rpy="0 0 0" xyz="0 0 0"/>
      <geometry>
        <mesh filename="package://hdt_angler_description/meshes/H024840 - A35 M-2 DRIVE MODULE, SHAREABLE.STL"/>
      </geometry>
      <material name="black"/>
    </visual>
    <inertial>
      <origin rpy="0 0 0" xyz="0 0 0"/>
      <mass value="1"/>
      <inertia ixx="0.005" ixy="0.0" ixz="0.0" iyy="0.005" iyz="0.0" izz="0.005"/>
    </inertial>
  </link>
  <!-- drive 2 -->
  <joint name="drive2_joint" type="revolute">
    <axis xyz="0 0 1"/>
    <limit effort="60.0" lower="-1.57079632679" upper="1.57079632679" velocity="0.785398163397"/>
    <origin rpy="0 -1.57079632679 0" xyz="0.07155 0 0"/>
    <parent link="drive1_link"/>
    <child link="drive2_link"/>
    <dynamics damping="0.7" friction="0.0"/>
  </joint>
  <link name="drive2_link">
    <collision>
      <origin rpy="3.14159265359 0 0" xyz="0 0 0"/>
      <geometry>
        <mesh filename="package://hdt_angler_description/meshes/H024840 - A35 M-2 DRIVE MODULE, SHAREABLE.STL"/>
      </geometry>
    </collision>
    <visual>
      <origin rpy="3.14159265359 0 0" xyz="0 0 0"/>
      <geometry>
        <mesh filename="package://hdt_angler_description/meshes/H024840 - A35 M-2 DRIVE MODULE, SHAREABLE.STL"/>
      </geometry>
      <material name="black"/>
    </visual>
    <inertial>
      <origin rpy="3.14159265359 0 0" xyz="0 0 0"/>
      <mass value="1"/>
      <inertia ixx="0.005" ixy="0.0" ixz="0.0" iyy="0.005" iyz="0.0" izz="0.005"/>
    </inertial>
  </link>
  <!-- humerus -->
  <joint name="humerus_joint" type="fixed">
    <origin rpy="0 0 0" xyz="0.17855 0 0"/>
    <parent link="drive2_link"/>
    <child link="humerus_link"/>
  </joint>
  <link name="humerus_link">
    <collision>
      <origin rpy="0 0 0" xyz="0 0 0"/>
      <geometry>
        <mesh filename="package://hdt_angler_description/meshes/H024847 - A35 M-2 PROXIMAL TUBE ASSY - SHAREABLE.STL"/>
      </geometry>
    </collision>
    <visual>
      <origin rpy="0 0 0" xyz="0 0 0"/>
      <geometry>
        <mesh filename="package://hdt_angler_description/meshes/H024847 - A35 M-2 PROXIMAL TUBE ASSY - SHAREABLE.STL"/>
      </geometry>
      <material name="black"/>
    </visual>
    <inertial>
      <origin rpy="0 0 0" xyz="0 0 0"/>
      <mass value="1"/>
      <inertia ixx="0.005" ixy="0.0" ixz="0.0" iyy="0.005" iyz="0.0" izz="0.005"/>
    </inertial>
  </link>
  <!-- elbow -->
  <joint name="elbow_joint" type="fixed">
    <origin rpy="0 0 0" xyz="0.17855 0 0"/>
    <parent link="humerus_link"/>
    <child link="elbow_link"/>
  </joint>
  <link name="elbow_link">
    <collision>
      <origin rpy="0 3.14159265359 0" xyz="0 0 0"/>
      <geometry>
        <mesh filename="package://hdt_angler_description/meshes/H024840 - A35 M-2 DRIVE MODULE, SHAREABLE.STL"/>
      </geometry>
    </collision>
    <visual>
      <origin rpy="0 3.14159265359 0" xyz="0 0 0"/>
      <geometry>
        <mesh filename="package://hdt_angler_description/meshes/H024840 - A35 M-2 DRIVE MODULE, SHAREABLE.STL"/>
      </geometry>
      <material name="black"/>
    </visual>
    <inertial>
      <origin rpy="0 3.14159265359 0" xyz="0 0 0"/>
      <mass value="1"/>
      <inertia ixx="0.005" ixy="0.0" ixz="0.0" iyy="0.005" iyz="0.0" izz="0.005"/>
    </inertial>
  </link>
  <!-- drive 3 -->
  <joint name="drive3_joint" type="revolute">
    <axis xyz="0 0 1"/>
    <!-- position limits to match parameter settings on actuator -->
    <limit effort="60.0" lower="-4.49" upper="1.35" velocity="0.785398163397"/>
    <origin rpy="0 0 0" xyz="0 0 0.07155"/>
    <parent link="elbow_link"/>
    <child link="drive3_link"/>
    <dynamics damping="0.7" friction="0.0"/>
  </joint>
  <link name="drive3_link">
    <collision>
      <origin rpy="0 1.57079632679 -1.57079632679" xyz="0 0 0"/>
      <geometry>
        <mesh filename="package://hdt_angler_description/meshes/H024840 - A35 M-2 DRIVE MODULE, SHAREABLE.STL"/>
      </geometry>
    </collision>
    <visual>
      <origin rpy="0 1.57079632679 -1.57079632679" xyz="0 0 0"/>
      <geometry>
        <mesh filename="package://hdt_angler_description/meshes/H024840 - A35 M-2 DRIVE MODULE, SHAREABLE.STL"/>
      </geometry>
      <material name="black"/>
    </visual>
    <inertial>
      <origin rpy="0 1.57079632679 -1.57079632679" xyz="0 0 0"/>
      <mass value="1"/>
      <inertia ixx="0.005" ixy="0.0" ixz="0.0" iyy="0.005" iyz="0.0" izz="0.005"/>
    </inertial>
  </link>
  <!-- drive 4 -->
  <joint name="drive4_joint" type="revolute">
    <axis xyz="0 0 1"/>
    <limit effort="60.0" lower="-6.28318530718" upper="6.28318530718" velocity="0.785398163397"/>
    <origin rpy="-1.57079632679 0 0" xyz="0 0.142 0"/>
    <parent link="drive3_link"/>
    <child link="drive4_link"/>
    <dynamics damping="0.7" friction="0.0"/>
  </joint>
  <link name="drive4_link">
    <collision>
      <origin rpy="3.14159265359 0 0" xyz="0 0 0"/>
      <geometry>
        <mesh filename="package://hdt_angler_description/meshes/H024848 - A35 M-2 DISTAL TUBE ASSY - SHAREABLE.STL"/>
      </geometry>
    </collision>
    <visual>
      <origin rpy="3.14159265359 0 0" xyz="0 0 0"/>
      <geometry>
        <mesh filename="package://hdt_angler_description/meshes/H024848 - A35 M-2 DISTAL TUBE ASSY - SHAREABLE.STL"/>
      </geometry>
      <material name="black"/>
    </visual>
    <inertial>
      <origin rpy="3.14159265359 0 0" xyz="0 0 0"/>
      <mass value="1"/>
      <inertia ixx="0.005" ixy="0.0" ixz="0.0" iyy="0.005" iyz="0.0" izz="0.005"/>
    </inertial>
  </link>
  <!-- wrist -->
  <joint name="wrist_joint" type="fixed">
    <origin rpy="1.57079632679 -1.57079632679 3.14159265359" xyz="0 0 0.12955"/>
    <parent link="drive4_link"/>
    <child link="wrist_link"/>
  </joint>
  <link name="wrist_link">
    <collision>
      <origin rpy="0 0 3.14159265359" xyz="0 0 0"/>
      <geometry>
        <mesh filename="package://hdt_angler_description/meshes/H024840 - A35 M-2 DRIVE MODULE, SHAREABLE.STL"/>
      </geometry>
    </collision>
    <visual>
      <origin rpy="0 0 3.14159265359" xyz="0 0 0"/>
      <geometry>
        <mesh filename="package://hdt_angler_description/meshes/H024840 - A35 M-2 DRIVE MODULE, SHAREABLE.STL"/>
      </geometry>
      <material name="black"/>
    </visual>
    <inertial>
      <origin rpy="0 0 3.14159265359" xyz="0 0 0"/>
      <mass value="1"/>
      <inertia ixx="0.005" ixy="0.0" ixz="0.0" iyy="0.005" iyz="0.0" izz="0.005"/>
    </inertial>
  </link>
  <!-- drive 5 -->
  <joint name="drive5_joint" type="revolute">
    <axis xyz="0 0 1"/>
    <limit effort="60.0" lower="-6.28318530718" upper="6.28318530718" velocity="0.785398163397"/>
    <origin rpy="3.14159265359 0 0" xyz="0 0 -0.07155"/>
    <parent link="wrist_link"/>
    <child link="drive5_link"/>
    <dynamics damping="0.7" friction="0.0"/>
  </joint>
  <link name="drive5_link">
    <collision>
      <origin rpy="0 1.57079632679 3.14159265359" xyz="0 0 0"/>
      <geometry>
        <mesh filename="package://hdt_angler_description/meshes/H024840 - A35 M-2 DRIVE MODULE, SHAREABLE.STL"/>
      </geometry>
    </collision>
    <visual>
      <origin rpy="0 1.57079632679 3.14159265359" xyz="0 0 0"/>
      <geometry>
        <mesh filename="package://hdt_angler_description/meshes/H024840 - A35 M-2 DRIVE MODULE, SHAREABLE.STL"/>
      </geometry>
      <material name="black"/>
    </visual>
    <inertial>
      <origin rpy="0 0 0" xyz="0 0 0"/>
      <mass value="1"/>
      <inertia ixx="0.005" ixy="0.0" ixz="0.0" iyy="0.005" iyz="0.0" izz="0.005"/>
    </inertial>
  </link>
  <!-- drive 6 -->
  <joint name="drive6_joint" type="revolute">
    <axis xyz="0 0 1"/>
    <limit effort="60.0" lower="-6.28318530718" upper="6.28318530718" velocity="0.785398163397"/>
    <origin rpy="0 1.57079632679 0" xyz="0.0885 0 0"/>
    <parent link="drive5_link"/>
    <child link="drive6_link"/>
    <dynamics damping="0.7" friction="0.0"/>
  </joint>
  <link name="drive6_link">
    <collision>
      <origin rpy="0 1.57079632679 -1.57079632679" xyz="0 0 0"/>
      <geometry>
        <mesh filename="package://hdt_angler_description/meshes/H024842 - A35 M-2 PINCER ASSY - SHAREABLE, UNDERWATER.STL"/>
      </geometry>
    </collision>
    <visual>
      <origin rpy="0 1.57079632679 -1.57079632679" xyz="0 0 0"/>
      <geometry>
        <mesh filename="package://hdt_angler_description/meshes/H024842 - A35 M-2 PINCER ASSY - SHAREABLE, UNDERWATER.STL"/>
      </geometry>
      <material name="black"/>
    </visual>
    <inertial>
      <origin rpy="0 0 0" xyz="0 0 0"/>
      <mass value="1"/>
      <inertia ixx="0.005" ixy="0.0" ixz="0.0" iyy="0.005" iyz="0.0" izz="0.005"/>
    </inertial>
  </link>
  <!-- Pincers -->
  <joint name="pincer_joint" type="revolute">
    <hdt id="10" inertia="0.075" kmax="150" kmin="75"/>
    <axis xyz="0 0 1"/>
    <limit effort="60.0" lower="-0.2" upper="0.9" velocity="0.5"/>
    <origin rpy="-1.57079632679 -1.57079632679 0" xyz="0.0135 0 0.0375"/>
    <parent link="drive6_link"/>
    <child link="pincer_link"/>
    <dynamics damping="0.7" friction="0.0"/>
  </joint>
  <link name="pincer_link">
    <collision>
      <origin rpy="3.14159265359 0 0" xyz="0 0 0"/>
      <geometry>
        <mesh filename="package://hdt_angler_description/meshes/H022927 - A35 PINCER FINGER, LONG, OVERMOLD ASSY - SHAREABLE.STL"/>
      </geometry>
    </collision>
    <visual>
      <origin rpy="3.14159265359 0 0" xyz="0 0 0"/>
      <geometry>
        <mesh filename="package://hdt_angler_description/meshes/H022927 - A35 PINCER FINGER, LONG, OVERMOLD ASSY - SHAREABLE.STL"/>
      </geometry>
      <material name="black"/>
    </visual>
  </link>
  <!-- EE 2 -->
  <!-- THIS IS THE SECOND PINCER, NEEDS TO MOVE EQUAL BUT OPPOSITE AS PINCER 1 -->
  <joint name="pincer_joint2" type="revolute">
    <!--<hdt id="10b" kmin="75" kmax="150" inertia="0.075"/>-->
    <axis xyz="0 0 1"/>
    <origin rpy="-1.57079632679 -1.57079632679 3.14159265359" xyz="-0.0135 0 0.0375"/>
    <parent link="drive6_link"/>
    <child link="pincer_link2"/>
    <calibration rising="0.0"/>
    <dynamics damping="0.7" friction="0.0"/>
    <limit effort="60.0" lower="-0.2" upper="1" velocity="0.5"/>
    <mimic joint="pincer_joint" multiplier="1" offset="0.0"/>
  </joint>
  <link name="pincer_link2">
    <collision>
      <origin rpy="3.14159265359 0 0" xyz="0 0 0"/>
      <geometry>
        <mesh filename="package://hdt_angler_description/meshes/H022927 - A35 PINCER FINGER, LONG, OVERMOLD ASSY - SHAREABLE.STL"/>
      </geometry>
    </collision>
    <visual>
      <origin rpy="3.14159265359 0 0" xyz="0 0 0"/>
      <geometry>
        <mesh filename="package://hdt_angler_description/meshes/H022927 - A35 PINCER FINGER, LONG, OVERMOLD ASSY - SHAREABLE.STL"/>
      </geometry>
      <material name="black"/>
    </visual>
  </link>
  <!-- endpoint -->
  <joint name="endpoint_joint" type="fixed">
    <origin rpy="1.57079632679 -1.57079632679 0" xyz="0 0 0.17"/>
    <parent link="drive6_link"/>
    <child link="endpoint_link"/>
  </joint>
  <link name="endpoint_link">
    </link>
</robot>

